Traceback (most recent call last):
  File "/home/aurve/fast-api-clean/venv/lib/python3.10/site-packages/pymysql/connections.py", line 644, in connect
    sock = socket.create_connection(
  File "/usr/lib/python3.10/socket.py", line 845, in create_connection
    raise err
  File "/usr/lib/python3.10/socket.py", line 833, in create_connection
    sock.connect(sa)
ConnectionRefusedError: [Errno 111] Connection refused

During handling of the above exception, another exception occurred:

Traceback (most recent call last):
  File "/home/aurve/fast-api-clean/venv/lib/python3.10/site-packages/sqlalchemy/engine/base.py", line 145, in __init__
    self._dbapi_connection = engine.raw_connection()
  File "/home/aurve/fast-api-clean/venv/lib/python3.10/site-packages/sqlalchemy/engine/base.py", line 3292, in raw_connection
    return self.pool.connect()
  File "/home/aurve/fast-api-clean/venv/lib/python3.10/site-packages/sqlalchemy/pool/base.py", line 452, in connect
    return _ConnectionFairy._checkout(self)
  File "/home/aurve/fast-api-clean/venv/lib/python3.10/site-packages/sqlalchemy/pool/base.py", line 1269, in _checkout
    fairy = _ConnectionRecord.checkout(pool)
  File "/home/aurve/fast-api-clean/venv/lib/python3.10/site-packages/sqlalchemy/pool/base.py", line 716, in checkout
    rec = pool._do_get()
  File "/home/aurve/fast-api-clean/venv/lib/python3.10/site-packages/sqlalchemy/pool/impl.py", line 169, in _do_get
    with util.safe_reraise():
  File "/home/aurve/fast-api-clean/venv/lib/python3.10/site-packages/sqlalchemy/util/langhelpers.py", line 146, in __exit__
    raise exc_value.with_traceback(exc_tb)
  File "/home/aurve/fast-api-clean/venv/lib/python3.10/site-packages/sqlalchemy/pool/impl.py", line 167, in _do_get
    return self._create_connection()
  File "/home/aurve/fast-api-clean/venv/lib/python3.10/site-packages/sqlalchemy/pool/base.py", line 393, in _create_connection
    return _ConnectionRecord(self)
  File "/home/aurve/fast-api-clean/venv/lib/python3.10/site-packages/sqlalchemy/pool/base.py", line 678, in __init__
    self.__connect()
  File "/home/aurve/fast-api-clean/venv/lib/python3.10/site-packages/sqlalchemy/pool/base.py", line 902, in __connect
    with util.safe_reraise():
  File "/home/aurve/fast-api-clean/venv/lib/python3.10/site-packages/sqlalchemy/util/langhelpers.py", line 146, in __exit__
    raise exc_value.with_traceback(exc_tb)
  File "/home/aurve/fast-api-clean/venv/lib/python3.10/site-packages/sqlalchemy/pool/base.py", line 898, in __connect
    self.dbapi_connection = connection = pool._invoke_creator(self)
  File "/home/aurve/fast-api-clean/venv/lib/python3.10/site-packages/sqlalchemy/engine/create.py", line 637, in connect
    return dialect.connect(*cargs, **cparams)
  File "/home/aurve/fast-api-clean/venv/lib/python3.10/site-packages/sqlalchemy/engine/default.py", line 616, in connect
    return self.loaded_dbapi.connect(*cargs, **cparams)
  File "/home/aurve/fast-api-clean/venv/lib/python3.10/site-packages/pymysql/connections.py", line 358, in __init__
    self.connect()
  File "/home/aurve/fast-api-clean/venv/lib/python3.10/site-packages/pymysql/connections.py", line 711, in connect
    raise exc
pymysql.err.OperationalError: (2003, "Can't connect to MySQL server on 'localhost' ([Errno 111] Connection refused)")

The above exception was the direct cause of the following exception:

Traceback (most recent call last):
  File "/home/aurve/fast-api-clean/venv/bin/uvicorn", line 8, in <module>
    sys.exit(main())
  File "/home/aurve/fast-api-clean/venv/lib/python3.10/site-packages/click/core.py", line 1157, in __call__
    return self.main(*args, **kwargs)
  File "/home/aurve/fast-api-clean/venv/lib/python3.10/site-packages/click/core.py", line 1078, in main
    rv = self.invoke(ctx)
  File "/home/aurve/fast-api-clean/venv/lib/python3.10/site-packages/click/core.py", line 1434, in invoke
    return ctx.invoke(self.callback, **ctx.params)
  File "/home/aurve/fast-api-clean/venv/lib/python3.10/site-packages/click/core.py", line 783, in invoke
    return __callback(*args, **kwargs)
  File "/home/aurve/fast-api-clean/venv/lib/python3.10/site-packages/uvicorn/main.py", line 416, in main
    run(
  File "/home/aurve/fast-api-clean/venv/lib/python3.10/site-packages/uvicorn/main.py", line 587, in run
    server.run()
  File "/home/aurve/fast-api-clean/venv/lib/python3.10/site-packages/uvicorn/server.py", line 61, in run
    return asyncio.run(self.serve(sockets=sockets))
  File "/usr/lib/python3.10/asyncio/runners.py", line 44, in run
    return loop.run_until_complete(main)
  File "/usr/lib/python3.10/asyncio/base_events.py", line 649, in run_until_complete
    return future.result()
  File "/home/aurve/fast-api-clean/venv/lib/python3.10/site-packages/uvicorn/server.py", line 68, in serve
    config.load()
  File "/home/aurve/fast-api-clean/venv/lib/python3.10/site-packages/uvicorn/config.py", line 467, in load
    self.loaded_app = import_from_string(self.app)
  File "/home/aurve/fast-api-clean/venv/lib/python3.10/site-packages/uvicorn/importer.py", line 21, in import_from_string
    module = importlib.import_module(module_str)
  File "/usr/lib/python3.10/importlib/__init__.py", line 126, in import_module
    return _bootstrap._gcd_import(name[level:], package, level)
  File "<frozen importlib._bootstrap>", line 1050, in _gcd_import
  File "<frozen importlib._bootstrap>", line 1027, in _find_and_load
  File "<frozen importlib._bootstrap>", line 1006, in _find_and_load_unlocked
  File "<frozen importlib._bootstrap>", line 688, in _load_unlocked
  File "<frozen importlib._bootstrap_external>", line 883, in exec_module
  File "<frozen importlib._bootstrap>", line 241, in _call_with_frames_removed
  File "/home/aurve/fast-api-clean/main.py", line 26, in <module>
    models.Base.metadata.create_all(bind=engine)
  File "/home/aurve/fast-api-clean/venv/lib/python3.10/site-packages/sqlalchemy/sql/schema.py", line 5828, in create_all
    bind._run_ddl_visitor(
  File "/home/aurve/fast-api-clean/venv/lib/python3.10/site-packages/sqlalchemy/engine/base.py", line 3242, in _run_ddl_visitor
    with self.begin() as conn:
  File "/usr/lib/python3.10/contextlib.py", line 135, in __enter__
    return next(self.gen)
  File "/home/aurve/fast-api-clean/venv/lib/python3.10/site-packages/sqlalchemy/engine/base.py", line 3232, in begin
    with self.connect() as conn:
  File "/home/aurve/fast-api-clean/venv/lib/python3.10/site-packages/sqlalchemy/engine/base.py", line 3268, in connect
    return self._connection_cls(self)
  File "/home/aurve/fast-api-clean/venv/lib/python3.10/site-packages/sqlalchemy/engine/base.py", line 147, in __init__
    Connection._handle_dbapi_exception_noconnection(
  File "/home/aurve/fast-api-clean/venv/lib/python3.10/site-packages/sqlalchemy/engine/base.py", line 2430, in _handle_dbapi_exception_noconnection
    raise sqlalchemy_exception.with_traceback(exc_info[2]) from e
  File "/home/aurve/fast-api-clean/venv/lib/python3.10/site-packages/sqlalchemy/engine/base.py", line 145, in __init__
    self._dbapi_connection = engine.raw_connection()
  File "/home/aurve/fast-api-clean/venv/lib/python3.10/site-packages/sqlalchemy/engine/base.py", line 3292, in raw_connection
    return self.pool.connect()
  File "/home/aurve/fast-api-clean/venv/lib/python3.10/site-packages/sqlalchemy/pool/base.py", line 452, in connect
    return _ConnectionFairy._checkout(self)
  File "/home/aurve/fast-api-clean/venv/lib/python3.10/site-packages/sqlalchemy/pool/base.py", line 1269, in _checkout
    fairy = _ConnectionRecord.checkout(pool)
  File "/home/aurve/fast-api-clean/venv/lib/python3.10/site-packages/sqlalchemy/pool/base.py", line 716, in checkout
    rec = pool._do_get()
  File "/home/aurve/fast-api-clean/venv/lib/python3.10/site-packages/sqlalchemy/pool/impl.py", line 169, in _do_get
    with util.safe_reraise():
  File "/home/aurve/fast-api-clean/venv/lib/python3.10/site-packages/sqlalchemy/util/langhelpers.py", line 146, in __exit__
    raise exc_value.with_traceback(exc_tb)
  File "/home/aurve/fast-api-clean/venv/lib/python3.10/site-packages/sqlalchemy/pool/impl.py", line 167, in _do_get
    return self._create_connection()
  File "/home/aurve/fast-api-clean/venv/lib/python3.10/site-packages/sqlalchemy/pool/base.py", line 393, in _create_connection
    return _ConnectionRecord(self)
  File "/home/aurve/fast-api-clean/venv/lib/python3.10/site-packages/sqlalchemy/pool/base.py", line 678, in __init__
    self.__connect()
  File "/home/aurve/fast-api-clean/venv/lib/python3.10/site-packages/sqlalchemy/pool/base.py", line 902, in __connect
    with util.safe_reraise():
  File "/home/aurve/fast-api-clean/venv/lib/python3.10/site-packages/sqlalchemy/util/langhelpers.py", line 146, in __exit__
    raise exc_value.with_traceback(exc_tb)
  File "/home/aurve/fast-api-clean/venv/lib/python3.10/site-packages/sqlalchemy/pool/base.py", line 898, in __connect
    self.dbapi_connection = connection = pool._invoke_creator(self)
  File "/home/aurve/fast-api-clean/venv/lib/python3.10/site-packages/sqlalchemy/engine/create.py", line 637, in connect
    return dialect.connect(*cargs, **cparams)
  File "/home/aurve/fast-api-clean/venv/lib/python3.10/site-packages/sqlalchemy/engine/default.py", line 616, in connect
    return self.loaded_dbapi.connect(*cargs, **cparams)
  File "/home/aurve/fast-api-clean/venv/lib/python3.10/site-packages/pymysql/connections.py", line 358, in __init__
    self.connect()
  File "/home/aurve/fast-api-clean/venv/lib/python3.10/site-packages/pymysql/connections.py", line 711, in connect
    raise exc
sqlalchemy.exc.OperationalError: (pymysql.err.OperationalError) (2003, "Can't connect to MySQL server on 'localhost' ([Errno 111] Connection refused)")
(Background on this error at: https://sqlalche.me/e/20/e3q8)
Traceback (most recent call last):
  File "/home/aurve/fast-api-clean/venv/lib/python3.10/site-packages/pymysql/connections.py", line 644, in connect
    sock = socket.create_connection(
  File "/usr/lib/python3.10/socket.py", line 845, in create_connection
    raise err
  File "/usr/lib/python3.10/socket.py", line 833, in create_connection
    sock.connect(sa)
ConnectionRefusedError: [Errno 111] Connection refused

During handling of the above exception, another exception occurred:

Traceback (most recent call last):
  File "/home/aurve/fast-api-clean/venv/lib/python3.10/site-packages/sqlalchemy/engine/base.py", line 145, in __init__
    self._dbapi_connection = engine.raw_connection()
  File "/home/aurve/fast-api-clean/venv/lib/python3.10/site-packages/sqlalchemy/engine/base.py", line 3292, in raw_connection
    return self.pool.connect()
  File "/home/aurve/fast-api-clean/venv/lib/python3.10/site-packages/sqlalchemy/pool/base.py", line 452, in connect
    return _ConnectionFairy._checkout(self)
  File "/home/aurve/fast-api-clean/venv/lib/python3.10/site-packages/sqlalchemy/pool/base.py", line 1269, in _checkout
    fairy = _ConnectionRecord.checkout(pool)
  File "/home/aurve/fast-api-clean/venv/lib/python3.10/site-packages/sqlalchemy/pool/base.py", line 716, in checkout
    rec = pool._do_get()
  File "/home/aurve/fast-api-clean/venv/lib/python3.10/site-packages/sqlalchemy/pool/impl.py", line 169, in _do_get
    with util.safe_reraise():
  File "/home/aurve/fast-api-clean/venv/lib/python3.10/site-packages/sqlalchemy/util/langhelpers.py", line 146, in __exit__
    raise exc_value.with_traceback(exc_tb)
  File "/home/aurve/fast-api-clean/venv/lib/python3.10/site-packages/sqlalchemy/pool/impl.py", line 167, in _do_get
    return self._create_connection()
  File "/home/aurve/fast-api-clean/venv/lib/python3.10/site-packages/sqlalchemy/pool/base.py", line 393, in _create_connection
    return _ConnectionRecord(self)
  File "/home/aurve/fast-api-clean/venv/lib/python3.10/site-packages/sqlalchemy/pool/base.py", line 678, in __init__
    self.__connect()
  File "/home/aurve/fast-api-clean/venv/lib/python3.10/site-packages/sqlalchemy/pool/base.py", line 902, in __connect
    with util.safe_reraise():
  File "/home/aurve/fast-api-clean/venv/lib/python3.10/site-packages/sqlalchemy/util/langhelpers.py", line 146, in __exit__
    raise exc_value.with_traceback(exc_tb)
  File "/home/aurve/fast-api-clean/venv/lib/python3.10/site-packages/sqlalchemy/pool/base.py", line 898, in __connect
    self.dbapi_connection = connection = pool._invoke_creator(self)
  File "/home/aurve/fast-api-clean/venv/lib/python3.10/site-packages/sqlalchemy/engine/create.py", line 637, in connect
    return dialect.connect(*cargs, **cparams)
  File "/home/aurve/fast-api-clean/venv/lib/python3.10/site-packages/sqlalchemy/engine/default.py", line 616, in connect
    return self.loaded_dbapi.connect(*cargs, **cparams)
  File "/home/aurve/fast-api-clean/venv/lib/python3.10/site-packages/pymysql/connections.py", line 358, in __init__
    self.connect()
  File "/home/aurve/fast-api-clean/venv/lib/python3.10/site-packages/pymysql/connections.py", line 711, in connect
    raise exc
pymysql.err.OperationalError: (2003, "Can't connect to MySQL server on 'localhost' ([Errno 111] Connection refused)")

The above exception was the direct cause of the following exception:

Traceback (most recent call last):
  File "/home/aurve/fast-api-clean/venv/bin/uvicorn", line 8, in <module>
    sys.exit(main())
  File "/home/aurve/fast-api-clean/venv/lib/python3.10/site-packages/click/core.py", line 1157, in __call__
    return self.main(*args, **kwargs)
  File "/home/aurve/fast-api-clean/venv/lib/python3.10/site-packages/click/core.py", line 1078, in main
    rv = self.invoke(ctx)
  File "/home/aurve/fast-api-clean/venv/lib/python3.10/site-packages/click/core.py", line 1434, in invoke
    return ctx.invoke(self.callback, **ctx.params)
  File "/home/aurve/fast-api-clean/venv/lib/python3.10/site-packages/click/core.py", line 783, in invoke
    return __callback(*args, **kwargs)
  File "/home/aurve/fast-api-clean/venv/lib/python3.10/site-packages/uvicorn/main.py", line 416, in main
    run(
  File "/home/aurve/fast-api-clean/venv/lib/python3.10/site-packages/uvicorn/main.py", line 587, in run
    server.run()
  File "/home/aurve/fast-api-clean/venv/lib/python3.10/site-packages/uvicorn/server.py", line 61, in run
    return asyncio.run(self.serve(sockets=sockets))
  File "/usr/lib/python3.10/asyncio/runners.py", line 44, in run
    return loop.run_until_complete(main)
  File "/usr/lib/python3.10/asyncio/base_events.py", line 649, in run_until_complete
    return future.result()
  File "/home/aurve/fast-api-clean/venv/lib/python3.10/site-packages/uvicorn/server.py", line 68, in serve
    config.load()
  File "/home/aurve/fast-api-clean/venv/lib/python3.10/site-packages/uvicorn/config.py", line 467, in load
    self.loaded_app = import_from_string(self.app)
  File "/home/aurve/fast-api-clean/venv/lib/python3.10/site-packages/uvicorn/importer.py", line 21, in import_from_string
    module = importlib.import_module(module_str)
  File "/usr/lib/python3.10/importlib/__init__.py", line 126, in import_module
    return _bootstrap._gcd_import(name[level:], package, level)
  File "<frozen importlib._bootstrap>", line 1050, in _gcd_import
  File "<frozen importlib._bootstrap>", line 1027, in _find_and_load
  File "<frozen importlib._bootstrap>", line 1006, in _find_and_load_unlocked
  File "<frozen importlib._bootstrap>", line 688, in _load_unlocked
  File "<frozen importlib._bootstrap_external>", line 883, in exec_module
  File "<frozen importlib._bootstrap>", line 241, in _call_with_frames_removed
  File "/home/aurve/fast-api-clean/main.py", line 26, in <module>
    models.Base.metadata.create_all(bind=engine)
  File "/home/aurve/fast-api-clean/venv/lib/python3.10/site-packages/sqlalchemy/sql/schema.py", line 5828, in create_all
    bind._run_ddl_visitor(
  File "/home/aurve/fast-api-clean/venv/lib/python3.10/site-packages/sqlalchemy/engine/base.py", line 3242, in _run_ddl_visitor
    with self.begin() as conn:
  File "/usr/lib/python3.10/contextlib.py", line 135, in __enter__
    return next(self.gen)
  File "/home/aurve/fast-api-clean/venv/lib/python3.10/site-packages/sqlalchemy/engine/base.py", line 3232, in begin
    with self.connect() as conn:
  File "/home/aurve/fast-api-clean/venv/lib/python3.10/site-packages/sqlalchemy/engine/base.py", line 3268, in connect
    return self._connection_cls(self)
  File "/home/aurve/fast-api-clean/venv/lib/python3.10/site-packages/sqlalchemy/engine/base.py", line 147, in __init__
    Connection._handle_dbapi_exception_noconnection(
  File "/home/aurve/fast-api-clean/venv/lib/python3.10/site-packages/sqlalchemy/engine/base.py", line 2430, in _handle_dbapi_exception_noconnection
    raise sqlalchemy_exception.with_traceback(exc_info[2]) from e
  File "/home/aurve/fast-api-clean/venv/lib/python3.10/site-packages/sqlalchemy/engine/base.py", line 145, in __init__
    self._dbapi_connection = engine.raw_connection()
  File "/home/aurve/fast-api-clean/venv/lib/python3.10/site-packages/sqlalchemy/engine/base.py", line 3292, in raw_connection
    return self.pool.connect()
  File "/home/aurve/fast-api-clean/venv/lib/python3.10/site-packages/sqlalchemy/pool/base.py", line 452, in connect
    return _ConnectionFairy._checkout(self)
  File "/home/aurve/fast-api-clean/venv/lib/python3.10/site-packages/sqlalchemy/pool/base.py", line 1269, in _checkout
    fairy = _ConnectionRecord.checkout(pool)
  File "/home/aurve/fast-api-clean/venv/lib/python3.10/site-packages/sqlalchemy/pool/base.py", line 716, in checkout
    rec = pool._do_get()
  File "/home/aurve/fast-api-clean/venv/lib/python3.10/site-packages/sqlalchemy/pool/impl.py", line 169, in _do_get
    with util.safe_reraise():
  File "/home/aurve/fast-api-clean/venv/lib/python3.10/site-packages/sqlalchemy/util/langhelpers.py", line 146, in __exit__
    raise exc_value.with_traceback(exc_tb)
  File "/home/aurve/fast-api-clean/venv/lib/python3.10/site-packages/sqlalchemy/pool/impl.py", line 167, in _do_get
    return self._create_connection()
  File "/home/aurve/fast-api-clean/venv/lib/python3.10/site-packages/sqlalchemy/pool/base.py", line 393, in _create_connection
    return _ConnectionRecord(self)
  File "/home/aurve/fast-api-clean/venv/lib/python3.10/site-packages/sqlalchemy/pool/base.py", line 678, in __init__
    self.__connect()
  File "/home/aurve/fast-api-clean/venv/lib/python3.10/site-packages/sqlalchemy/pool/base.py", line 902, in __connect
    with util.safe_reraise():
  File "/home/aurve/fast-api-clean/venv/lib/python3.10/site-packages/sqlalchemy/util/langhelpers.py", line 146, in __exit__
    raise exc_value.with_traceback(exc_tb)
  File "/home/aurve/fast-api-clean/venv/lib/python3.10/site-packages/sqlalchemy/pool/base.py", line 898, in __connect
    self.dbapi_connection = connection = pool._invoke_creator(self)
  File "/home/aurve/fast-api-clean/venv/lib/python3.10/site-packages/sqlalchemy/engine/create.py", line 637, in connect
    return dialect.connect(*cargs, **cparams)
  File "/home/aurve/fast-api-clean/venv/lib/python3.10/site-packages/sqlalchemy/engine/default.py", line 616, in connect
    return self.loaded_dbapi.connect(*cargs, **cparams)
  File "/home/aurve/fast-api-clean/venv/lib/python3.10/site-packages/pymysql/connections.py", line 358, in __init__
    self.connect()
  File "/home/aurve/fast-api-clean/venv/lib/python3.10/site-packages/pymysql/connections.py", line 711, in connect
    raise exc
sqlalchemy.exc.OperationalError: (pymysql.err.OperationalError) (2003, "Can't connect to MySQL server on 'localhost' ([Errno 111] Connection refused)")
(Background on this error at: https://sqlalche.me/e/20/e3q8)
INFO:     Started server process [1026]
INFO:     Waiting for application startup.
INFO:     Application startup complete.
INFO:     Uvicorn running on http://0.0.0.0:8000 (Press CTRL+C to quit)
INFO:     192.168.2.104:59286 - "GET /trip HTTP/1.1" 200 OK
INFO:     192.168.2.34:54392 - "GET /trip?limit=10&sort=latest HTTP/1.1" 200 OK
INFO:     192.168.2.34:54392 - "GET /trip?limit=10&sort=latest HTTP/1.1" 200 OK
INFO:     192.168.2.34:54392 - "GET /trip?limit=10&sort=latest HTTP/1.1" 200 OK
INFO:     192.168.2.34:54392 - "GET /trip?limit=10&sort=latest HTTP/1.1" 200 OK
INFO:     192.168.2.34:54417 - "GET /trip?limit=10&sort=latest HTTP/1.1" 200 OK
INFO:     192.168.2.34:54417 - "GET /trip?limit=10&sort=latest HTTP/1.1" 200 OK
INFO:     192.168.2.34:54435 - "GET /trip?limit=10&sort=latest HTTP/1.1" 200 OK
INFO:     192.168.2.34:54435 - "GET /trip?limit=10&sort=latest HTTP/1.1" 200 OK
